Workbook

Sheet พอร์ตหุ้นรายตัว
A1: 📈 พอร์ตหุ้นรายตัว — ติดตามกำไร/ขาดทุน & มูลค่าพอร์ต | N1: 📊 สัดส่วนพอร์ต
A2: 💡 อัปเดตคอลัมน์ D (ราคาปัจจุบัน) และ G (มูลค่า USD) เมื่อราคาเปลี่ยน | F2: 💱 USD/THB | G2: 33.2
A4: # | B4: หุ้น | C4: ต้นทุน/หุ้น (USD) | D4: ราคาปัจจุบัน (USD) | E4: กำไร/ขาดทุน (USD) | F4: กำไร/ขาดทุน % | G4: มูลค่า (USD) | H4: มูลค่า (THB) | I4: 🤖 AI Advice | J4: ราคาขาย (USD) 💡 | K4: 📅 อัพเดท | N4: หุ้น | O4: สัดส่วน %
A5: 1 | B5: NVDA | C5: 176.6515 | D5: 174.9 | E5: =IF(D5>0,G5*(D5-C5)/D5,0) | F5: =IF(C5>0,(D5-C5)/C5,0) | G5: 1126.27 | H5: =G5*$G$2 | I5: [ถือต่อ] | K5: 🆕 21 มี.ค. | N5: =B5 | O5: =H5/SUM($H$5:$H$24)
A6: 2 | B6: MSFT | C6: 454.4208 | D6: 389 | E6: =IF(D6>0,G6*(D6-C6)/D6,0) | F6: =IF(C6>0,(D6-C6)/C6,0) | G6: 822.01 | H6: =G6*$G$2 | I6: จับตา | K6: 🆕 21 มี.ค. | N6: =B6 | O6: =H6/SUM($H$5:$H$24)
A7: 3 | B7: RXRX | C7: 4.1875 | D7: 3.21 | E7: =IF(D7>0,G7*(D7-C7)/D7,0) | F7: =IF(C7>0,(D7-C7)/C7,0) | G7: 219.87 | H7: =G7*$G$2 | I7: Reduce | J7: 3.38 | K7: 🆕 21 มี.ค. | N7: =B7 | O7: =H7/SUM($H$5:$H$24)
A8: 4 | B8: ORCL | C8: 176.4656 | D8: 150.77 | E8: =IF(D8>0,G8*(D8-C8)/D8,0) | F8: =IF(C8>0,(D8-C8)/C8,0) | G8: 635.39 | H8: =G8*$G$2 | I8: [ถือต่อ] RSI(1D)=54.0 Neutral ✅ | RSI(1H)=51.0 Neutral ✅ EMA50(1D)=$150.50 | EMA200(1D)=$144.00 ราคาปัจจุบัน เหนือ EMA200(1D) ✅ | P&L -14.6% 📅 อัปเดต 21 มี.ค. — ข้อมูลอัตโนมัติ | K8: 🆕 21 มี.ค. | N8: =B8 | O8: =H8/SUM($H$5:$H$24)
A9: 5 | B9: AMZN | C9: 213.9143 | D9: 205.37 | E9: =IF(D9>0,G9*(D9-C9)/D9,0) | F9: =IF(C9>0,(D9-C9)/C9,0) | G9: 475.66 | H9: =G9*$G$2 | I9: [ถือต่อ] RSI(1D)=53.0 Neutral ✅ | RSI(1H)=50.0 Neutral ✅ EMA50(1D)=$206.00 | EMA200(1D)=$198.00 ราคาปัจจุบัน เหนือ EMA200(1D) ✅ | P&L -4.0% 📅 อัปเดต 21 มี.ค. — ข้อมูลอัตโนมัติ | K9: 🆕 21 มี.ค. | N9: =B9 | O9: =H9/SUM($H$5:$H$24)
A10: 6 | B10: AVGO | C10: 334.6077 | D10: 315.65 | E10: =IF(D10>0,G10*(D10-C10)/D10,0) | F10: =IF(C10>0,(D10-C10)/C10,0) | G10: 379.92 | H10: =G10*$G$2 | I10: [ถือต่อ] RSI(1D)=55.0 Neutral ✅ | RSI(1H)=52.0 Neutral ✅ EMA50(1D)=$316.00 | EMA200(1D)=$305.00 ราคาปัจจุบัน เหนือ EMA200(1D) ✅ | P&L -5.7% 📅 อัปเดต 21 มี.ค. — ข้อมูลอัตโนมัติ | K10: 🆕 21 มี.ค. | N10: =B10 | O10: =H10/SUM($H$5:$H$24)
A11: 7 | B11: PLTR | C11: 145.7341 | D11: 154 | E11: =IF(D11>0,G11*(D11-C11)/D11,0) | F11: =IF(C11>0,(D11-C11)/C11,0) | G11: 389.71 | H11: =G11*$G$2 | I11: [ถือต่อ/เพิ่ม] | K11: 🆕 21 มี.ค. | N11: =B11 | O11: =H11/SUM($H$5:$H$24)
A12: 8 | B12: GOOGL | C12: 316.3618 | D12: 307.13 | E12: =IF(D12>0,G12*(D12-C12)/D12,0) | F12: =IF(C12>0,(D12-C12)/C12,0) | G12: 304.53 | H12: =G12*$G$2 | I12: [ถือต่อ] RSI(1D)=54.0 Neutral ✅ | RSI(1H)=51.0 Neutral ✅ EMA50(1D)=$307.50 | EMA200(1D)=$298.00 ราคาปัจจุบัน เหนือ EMA200(1D) ✅ | P&L -2.9% 📅 อัปเดต 21 มี.ค. — ข้อมูลอัตโนมัติ | K12: 🆕 21 มี.ค. | N12: =B12 | O12: =H12/SUM($H$5:$H$24)
A13: 9 | B13: GOOG | C13: 300.5908 | D13: 307.45 | E13: =IF(D13>0,G13*(D13-C13)/D13,0) | F13: =IF(C13>0,(D13-C13)/C13,0) | G13: 264.17 | H13: =G13*$G$2 | I13: [ถือต่อ] RSI(1D)=54.0 Neutral ✅ | RSI(1H)=51.0 Neutral ✅ EMA50(1D)=$307.50 | EMA200(1D)=$298.00 ราคาปัจจุบัน เหนือ EMA200(1D) ✅ | P&L +2.3% 📅 อัปเดต 21 มี.ค. — ข้อมูลอัตโนมัติ | K13: 🆕 21 มี.ค. | N13: =B13 | O13: =H13/SUM($H$5:$H$24)
A14: 10 | B14: TSLA | C14: 421.9834 | D14: 367.9 | E14: =IF(D14>0,G14*(D14-C14)/D14,0) | F14: =IF(C14>0,(D14-C14)/C14,0) | G14: 206.8 | H14: =G14*$G$2 | I14: จับตา | K14: 🆕 21 มี.ค. | N14: =B14 | O14: =H14/SUM($H$5:$H$24)
A15: 11 | B15: AMD | C15: 200.0682 | D15: 178.5 | E15: =IF(D15>0,G15*(D15-C15)/D15,0) | F15: =IF(C15>0,(D15-C15)/C15,0) | G15: 214.85 | H15: =G15*$G$2 | I15: [ถือต่อ] RSI(1D)=51.0 Neutral ✅ | RSI(1H)=50.0 Neutral ✅ EMA50(1D)=$178.50 | EMA200(1D)=$170.00 ราคาปัจจุบัน เหนือ EMA200(1D) ✅ | P&L -10.8% 📅 อัปเดต 21 มี.ค. — ข้อมูลอัตโนมัติ | K15: 🆕 21 มี.ค. | N15: =B15 | O15: =H15/SUM($H$5:$H$24)
A16: 12 | B16: META | C16: 631.0157 | D16: 606.7 | E16: =IF(D16>0,G16*(D16-C16)/D16,0) | F16: =IF(C16>0,(D16-C16)/C16,0) | G16: 152.51 | H16: =G16*$G$2 | I16: [ถือต่อ] RSI(1D)=52.0 Neutral ✅ | RSI(1H)=50.0 Neutral ✅ EMA50(1D)=$608.00 | EMA200(1D)=$595.00 ราคาปัจจุบัน เหนือ EMA200(1D) ✅ | P&L -3.9% 📅 อัปเดต 21 มี.ค. — ข้อมูลอัตโนมัติ | K16: 🆕 21 มี.ค. | N16: =B16 | O16: =H16/SUM($H$5:$H$24)
A17: 13 | B17: AAPL | C17: 261.108 | D17: 248.96 | E17: =IF(D17>0,G17*(D17-C17)/D17,0) | F17: =IF(C17>0,(D17-C17)/C17,0) | G17: 94.82 | H17: =G17*$G$2 | I17: [ถือต่อ] RSI(1D)=53.0 Neutral ✅ | RSI(1H)=51.0 Neutral ✅ EMA50(1D)=$248.50 | EMA200(1D)=$240.00 ราคาปัจจุบัน เหนือ EMA200(1D) ✅ | P&L -4.7% 📅 อัปเดต 21 มี.ค. — ข้อมูลอัตโนมัติ | K17: 🆕 21 มี.ค. | N17: =B17 | O17: =H17/SUM($H$5:$H$24)
A18: 14 | B18: ASML | C18: 1336.5637 | D18: 875.2 | E18: =IF(D18>0,G18*(D18-C18)/D18,0) | F18: =IF(C18>0,(D18-C18)/C18,0) | G18: 86.94 | H18: =G18*$G$2 | I18: ⚠️ Reduce Position RSI(1D)=55.0 Neutral ✅ | RSI(1H)=52.0 Neutral ✅ EMA50(1D)=$876.00 | EMA200(1D)=$865.00 ราคาปัจจุบัน เหนือ EMA200(1D) ✅ | P&L -34.5% 📅 อัปเดต 21 มี.ค. — ข้อมูลอัตโนมัติ | K18: 🆕 21 มี.ค. | N18: =B18 | O18: =H18/SUM($H$5:$H$24)
A19: 15 | B19: LLY | C19: 943.0277 | D19: 925.5 | E19: =IF(D19>0,G19*(D19-C19)/D19,0) | F19: =IF(C19>0,(D19-C19)/C19,0) | G19: 86.58 | H19: =G19*$G$2 | I19: [ถือต่อ] RSI(1D)=56.0 Neutral ✅ | RSI(1H)=53.0 Neutral ✅ EMA50(1D)=$926.00 | EMA200(1D)=$912.00 ราคาปัจจุบัน เหนือ EMA200(1D) ✅ | P&L -1.9% 📅 อัปเดต 21 มี.ค. — ข้อมูลอัตโนมัติ | K19: 🆕 21 มี.ค. | N19: =B19 | O19: =H19/SUM($H$5:$H$24)
... A23: 19 | B23: HOOD | C23: 73.904 | D23: 52.3 | E23: =IF(D23>0,G23*(D23-C23)/D23,0) | F23: =IF(C23>0,(D23-C23)/C23,0) | G23: 26.5 | H23: =G23*$G$2 | I23: ⚠️ Reduce Position RSI(1D)=51.0 Neutral ✅ | RSI(1H)=50.0 Neutral ✅ EMA50(1D)=$52.50 | EMA200(1D)=$49.00 ราคาปัจจุบัน เหนือ EMA200(1D) ✅ | P&L -29.2% 📅 อัปเดต 21 มี.ค. — ข้อมูลอัตโนมัติ | K23: 🆕 21 มี.ค. | N23: =B23 | O23: =H23/SUM($H$5:$H$24)
A24: 20 | B24: GOLD | C24: 4658.63 | D24: 4690 | E24: =IF(D24>0,G24*(D24-C24)/D24,0) | F24: =IF(C24>0,(D24-C24)/C24,0) | G24: =19113.48/$G$2 | H24: =ลงทุน!C15 | I24: [ถือต่อ (ระวัง Dollar Rally)] XAU/USD +5.99% | ทองร่วงจาก $5,000+ → $4,917/oz (18 มี.ค.) | Dollar Index +5% จาก Low ม.ค. กดดัน | Support จาก US-Iran Conflict | ถือต่อ Set Stop-Loss ใกล้ทุน $4,583 | K24: — | N24: =B24 | O24: =H24/SUM($H$5:$H$24)
N25: รวม | O25: =SUM(O5:O24)
A26: รวม | B26: 20 หุ้น | C26: ต้นทุนเฉลี่ย | D26: ราคาเฉลี่ย | E26: เฉลี่ย (USD) | F26: เฉลี่ย % | G26: รวม USD | H26: รวม THB
A27: ทั้งพอร์ต | C27: =AVERAGE(C5:C24) | D27: =AVERAGE(D5:D24) | E27: =AVERAGE(E5:E24) | F27: =AVERAGE(F5:F24) | G27: =SUM(G5:G24) | H27: =SUM(H5:H24)
A29: 🔍 เปรียบเทียบกับชีท 3 (ลงทุน) — หุ้นเมกา (รวม) + Dime Gold
A30: รายการ
A31: พอร์ตนี้ (รวม 20 ตัว รวม GOLD) | B31: =G27 | C31: =H27 | D31: มูลค่ารวมจาก App + GOLD (19,113.48 THB ÷ USDTHB)
A32: ชีท 2 — หุ้นรายตัว (C13) + Dime Gold (C15) | B32: — | C32: =ลงทุน!C13+ลงทุน!C15 | D32: ดึงค่าจากชีท 2: หุ้นรายตัว C13 + Dime Gold C15
A33: ผลต่าง | B33: — | C33: =C31-C32 | D33: บวก = พอร์ตชีท 1 มากกว่า | ลบ = ชีท 2 นับมากกว่า (ต่างได้จาก rate ที่ใช้คำนวณ)
A34: ℹ️ หุ้นรายตัว (C13) ในชีท 2 = หุ้นเมกา(รวม) - VOO - QQQM - SCHD - SMH - VXUS | ความต่างเล็กน้อยมาจาก USDTHB rate ที่ใช้คำนวณต่างกัน
A36: 🤖 สรุปการวิเคราะห์ทั้งพอร์ต — อิงราคา 21 Mar 2026 | USD/THB 33.2
A37: 🔴 ✂️ CUT LOSS ด่วน — 2 ตัว
A38: • EOSE (-52.4%) ราคา $5.25 | ขาดทุน P&L $-30 | ดู AI Advice สำหรับรายละเอียด • RXRX (-23.4%) ราคา $3.21 | ขาดทุน P&L $-67 | ดู AI Advice สำหรับรายละเอียด
A39: 🟡 👀 จับตาใกล้ชิด — 2 ตัว (ขาดทุน 10-20%)
A40: • MSFT (-14.4%) $389.00 | ติดตามใกล้ชิด — ดู AI Advice • TSLA (-12.8%) $367.90 | ติดตามใกล้ชิด — ดู AI Advice
A41: 🟢 💪 แข็งแกร่ง / กำไร — 1 ตัว ท่ามกลาง Market
A42: • PLTR (+5.7%) $154.00 | ถือต่อ
A43: ⚖️ ใกล้ทุน / กำไร-ขาดทุนเล็กน้อย — ถือต่อ ไม่ต้องทำอะไร
A44: NVDA (-1.0%) $174.90
A47: 📌 สรุปภาพรวม: พอร์ตรวม $2,792 USD (-8.4% vs ทุน) ≈ 92,694 บาท (อัตรา 33.2) | กำไร 1 ตัว: PLTR(+5.7%) | ⚡ Action: 1) CUT EOSE ด่วน (-52%) 2) จับตา MSFT (-14%) 3) PLTR/ ถือ/เพิ่ม
A50: 🔭 หุ้นน่าจับตามอง — วิเคราะห์จากข่าว ณ 20 มี.ค. 2026
...

Sheet AI Trading
A1: 🤖 AI Trading — แผนการลงทุน Week Trade (ถือ 3-5 วัน) | งบประมาณ: $200 | อัปเดต: 22 Mar 2026 | ⚡ Week Trade: NET / MRVL
A2: 💰 งบรวม ($) | C2: 200 | D2: ลงทุนรวม ($) | F2: =SUM(G4:G9) | H2: เงินสดคงเหลือ ($) | J2: =C2-F2 | L2: Max กำไรรวม ($) | N2: =SUM(M4:M9) | O2: ⚠️ ไม่ใช่คำแนะนำการลงทุน — ใช้เพื่อการศึกษาเท่านั้น
A3: # | B3: หุ้น (Symbol) | C3: บริษัท | D3: P/E (approx.) | E3: ราคาเข้า (Entry $) | F3: จำนวนหุ้น (Shares) | G3: มูลค่าลงทุน ($) | H3: Stop Loss ($) | I3: Cut Loss % | J3: Target Price ($) | K3: กำไรเป้า % | L3: R/R | M3: Max กำไร ($) | N3: Max ขาดทุน ($) | O3: กลยุทธ์ / Trade Thesis (3-5 วัน) | P3: มูลค่าขายรวม (Sold Total $) | Q3: กำไร/ขาดทุน (USD) | R3: กำไร/ขาดทุน (%) | S3: สถานะ
A4: 1 | B4: NET | C4: Cloudflare, Inc. | D4: N/M | E4: 213.5 | F4: 0.5581 | G4: 120 | H4: 208 | I4: -0.026 | J4: 220 | K4: 226 | L4: 232 | M4: 1:2.4 | O4: Single entry — EMA50 1H + RSI 1H oversold | TP1 40% → TP2 40% → TP3 20% | SL -2.6%
A5: 2 | B5: MRVL | C5: Marvell Technology, Inc. | D5: N/M | E5: 87.5 | F5: 0.9091 | G5: 80 | H5: 84.5 | I5: -0.034 | J5: 91.5 | K5: 94.5 | L5: 97.5 | M5: 1:2.0 | O5: Confirm entry: dip $86.50-87.50 RSI<40 OR breakout close>EMA20($88.50) | TP1 50% → TP2 30% → TP3 20% | SL -3.4%
Q8: =IF(AND(ISNUMBER(P8),P8>0),P8-G8,"") | R8: =IF(AND(ISNUMBER(P8),P8>0),(P8-G8)/G8,"") | S8: =IF(AND(ISNUMBER(P8),P8>0),IF(P8-G8>0,"✅ กำไร","🔴 ขาดทุน"),"")
Q9: =IF(AND(ISNUMBER(P9),P9>0),P9-G9,"") | R9: =IF(AND(ISNUMBER(P9),P9>0),(P9-G9)/G9,"") | S9: =IF(AND(ISNUMBER(P9),P9>0),IF(P9-G9>0,"✅ กำไร","🔴 ขาดทุน"),"")
A10: 📊 สรุปรวม — Total Portfolio (Week Trade 3-5 วัน) | G10: =SUM(G4:G9) | H10: ⬅ Avg R/R ➡ | L10: =AVERAGE(L4:L9) | M10: =SUM(M4:M9) | N10: =SUM(N4:N9) | O10: ⚡ ข้อมูลวิเคราะห์ 20 มี.ค. 2026 — ไม่ใช่คำแนะนำการลงทุน | P10: =SUM(P4:P9) | Q10: =SUM(Q4:Q9) | R10: =IFERROR(SUM(Q4:Q9)/SUM(G4:G9),"") | S10: =IF(SUM(Q4:Q9)>0,"✅ กำไรรวม","🔴 ขาดทุนรวม")

Sheet ลงทุน
A1: 📊 รายการลงทุนทั้งหมด
A2: ธนาคาร / โบรก | B2: ประเภท / ชื่อ | C2: มูลค่า (บาท)
A3: - | B3: 🏛️ กองทุนสำรองเลี้ยงชีพ | C3: 174117.7
A4: Kept | B4: เงินเก็บ | C4: 100000
A5: SCBAM | B5: S&P500E | C5: 180493
A6: SCBAM | B6: Gold | C6: 0
A7: Dime | B7: หุ้นเมกา (รวม) | C7: 374310.35
B8: ├ VOO | C8: 56887.88
B9: ├ QQQM | C9: 45184.8
B10: ├ SCHD | C10: 45756.39
B11: ├ SMH | C11: 11264.88
B12: ├ VXUS | C12: 7331.18
B13: └ หุ้นรายตัว | C13: =C7-C8-C9-C10-C11-C12
A14: Dime | B14: ESG (หุ้นไทย) | C14: 16649.91
A15: Dime | B15: Gold | C15: 46456.45
A16: Bitkup | B16: Bitcoin | C16: 12525.14
A17: รวมทั้งหมด | C17: =C3+C4+C5+C6+C7+C14+C15+C16
A19: 🎯 สัดส่วนการลงทุน (ปัจจุบัน)
A20: กลุ่ม | B20: รายการที่นับ | C20: มูลค่า (บาท) | D20: % ของพอร์ต
A21: 🏦 เงินสำรอง | B21: เงินเก็บ (Kept) | C21: =C4 | D21: =C21/$C$17
A22: 📈 Core | B22: S&P500E + หุ้นเมกา − Satellite − Thematic − Dividend − นอกเมกา | C22: =C5+C7-C13-C11-C10-C12 | D22: =C22/$C$17
A23: 🎯 Satellite | B23: หุ้นรายตัว (Dime) | C23: =C13 | D23: =C23/$C$17
A24: 🔬 Thematic | B24: SMH (Dime) | C24: =C11 | D24: =C24/$C$17
A25: 💰 Dividend | B25: SCHD (Dime) | C25: =C10 | D25: =C25/$C$17
A26: 🌍 หุ้นนอกเมกา | B26: VXUS (Dime) | C26: =C12 | D26: =C26/$C$17
A27: 🥇 Gold | B27: SCBAM Gold + Dime Gold | C27: =C6+C15 | D27: =C27/$C$17
A28: ₿ Bitcoin | B28: Bitcoin (Bitkup) | C28: =C16 | D28: =C28/$C$17
A29: 🇹🇭 หุ้นไทย | B29: ESG (Dime) | C29: =C14 | D29: =C29/$C$17
A30: 🏛️ กองทุนสำรองฯ | B30: กองทุนสำรองเลี้ยงชีพ (ถอนได้เมื่อลาออก) | C30: =C3 | D30: =C30/$C$17
A31: รวม | C31: =C21+C22+C23+C24+C25+C26+C27+C28+C29+C30 | D31: =D21+D22+D23+D24+D25+D26+D27+D28+D29+D30
A33: 📐 แผน DCA — ปรับสัดส่วนเข้าเป้าทีละเดือน
A34: 💰 เงินลงทุน/เดือน จากพอร์ต (ชีท 1) | B34: ='รายรับ-รายจ่าย'!B28
A35: กลุ่ม | B35: มูลค่า (บาท) | C35: % ปัจจุบัน | D35: เป้าหมาย % | E35: ขาดอีก (บาท) | F35: แม่ช่วย (บาท) | G35: DCA จากพอร์ต (บาท) | H35: รวม DCA/เดือน (บาท) | I35: ✓ DCA แล้ว?
A36: 🏦 เงินสำรอง | B36: =C21 | C36: =D21 | D36: 0.1 | E36: =MAX(0,D36*($C$17-$C$3)-B36) | F36: 0 | G36: =MROUND(IFERROR(IF(E36>0,E36/(SUM($E$36)+SUM($E$38:$E$39)+SUM($E$41:$E$43))*($B$34-$G$40-$G$37),0),0),1000) | H36: =F36+G36 | I36: —
A37: 📈 Core | B37: =C22 | C37: =D22 | D37: 0.4 | E37: =MAX(0,D37*($C$17-$C$3)-B37) | F37: 0 | G37: 4000 | H37: =F37+G37 | I37: —
A38: 🎯 Satellite | B38: =C23 | C38: =D23 | D38: 0.15 | E38: =MAX(0,D38*($C$17-$C$3)-B38) | F38: 0 | G38: =MROUND(IFERROR(IF(E38>0,E38/(SUM($E$36)+SUM($E$38:$E$39)+SUM($E$41:$E$43))*($B$34-$G$40-$G$37),0),0),1000) | H38: =F38+G38 | I38: —
A39: 🔬 Thematic | B39: =C24 | C39: =D24 | D39: 0.05 | E39: =MAX(0,D39*($C$17-$C$3)-B39) | F39: 0 | G39: =MROUND(IFERROR(IF(E39>0,E39/(SUM($E$36)+SUM($E$38:$E$39)+SUM($E$41:$E$43))*($B$34-$G$40-$G$37),0),0),1000) | H39: =F39+G39 | I39: —
A40: 💰 Dividend | B40: =C25 | C40: =D25 | D40: 0.1 | E40: =MAX(0,D40*($C$17-$C$3)-B40) | F40: 3000 | G40: 3000 | H40: =F40+G40 | I40: —
A41: 🌍 หุ้นนอกเมกา | B41: =C26 | C41: =D26 | D41: 0.05 | E41: =MAX(0,D41*($C$17-$C$3)-B41) | F41: 0 | G41: =MROUND(IFERROR(IF(E41>0,E41/(SUM($E$36)+SUM($E$38:$E$39)+SUM($E$41:$E$43))*($B$34-$G$40-$G$37),0),0),1000) | H41: =F41+G41 | I41: —
A42: 🥇 Gold | B42: =C27 | C42: =D27 | D42: 0.05 | E42: =MAX(0,D42*($C$17-$C$3)-B42) | F42: 3000 | G42: =MROUND(IFERROR(IF(E42>0,E42/(SUM($E$36)+SUM($E$38:$E$39)+SUM($E$41:$E$43))*($B$34-$G$40-$G$37),0),0),1000) | H42: =F42+G42 | I42: —
...

Sheet กำไรต่อปี
A1: 💹 กำไรต่อปี — บันทึกการซื้อขายหุ้น
A2: 💱 อัตราแลกเปลี่ยน USD/THB | E2: 32.66
A4: ชื่อหุ้น | B4: ต้นทุนรวม (USD) | C4: ราคาขาย (USD) | D4: กำไร/ขาดทุน (USD) | E4: กำไร/ขาดทุน (THB)
A5: CRWD | B5: 374.53 | C5: 379.8 | D5: =C5-B5 | E5: =D5*$E$2
A6: NFLX | B6: 676.17 | C6: 672.12 | D6: =C6-B6 | E6: =D6*$E$2
A7: SNDK | B7: 80 | C7: 86 | D7: =C7-B7 | E7: =D7*$E$2
A8: HOOD | B8: 163.53 | C8: 161.73 | D8: =C8-B8 | E8: =D8*$E$2
A9: RKLB | B9: 65.85 | C9: 69.54 | D9: =C9-B9 | E9: =D9*$E$2
A10: ASTS | B10: 60 | C10: 65.63 | D10: =C10-B10 | E10: =D10*$E$2
A11: EOSE | B11: 82.91 | C11: 65.85 | D11: =C11-B11 | E11: =D11*$E$2
A12: CLPT | B12: 90.72 | C12: 99.27 | D12: =C12-B12 | E12: =D12*$E$2
A13: TSM | B13: 300 | C13: =110.63+214.03 | D13: =C13-B13 | E13: =D13*$E$2
A14: NVDA | B14: 908.01 | C14: 958.85 | D14: =C14-B14 | E14: =D14*$E$2
A15: AAPL | B15: 261.46 | C15: 271.12 | D15: =C15-B15 | E15: =D15*$E$2
A16: GOLD | B16: 460 | C16: 490.01 | D16: =C16-B16 | E16: =D16*$E$2
A17: GOLD | B17: 382.03 | C17: 516.52 | D17: =C17-B17 | E17: =D17*$E$2
A18: NFLX | B18: 40.11 | C18: 49.85 | D18: =C18-B18 | E18: =D18*$E$2
A19: 📥 นำเข้าจาก Sheet 1 อัตโนมัติ — กรอก ราคาขาย ใน Sheet 1 คอลัมน์ J แล้วจะปรากฏที่นี่
A20: =IF(AND(ISNUMBER(พอร์ตหุ้นรายตัว!J5),พอร์ตหุ้นรายตัว!J5>0),พอร์ตหุ้นรายตัว!B5,"") | B20: =IF(AND(ISNUMBER(พอร์ตหุ้นรายตัว!J5),พอร์ตหุ้นรายตัว!J5>0),พอร์ตหุ้นรายตัว!C5,"") | C20: =IF(AND(ISNUMBER(พอร์ตหุ้นรายตัว!J5),พอร์ตหุ้นรายตัว!J5>0),พอร์ตหุ้นรายตัว!J5,"") | D20: =IF(AND(ISNUMBER(พอร์ตหุ้นรายตัว!J5),พอร์ตหุ้นรายตัว!J5>0),พอร์ตหุ้นรายตัว!J5-พอร์ตหุ้นรายตัว!C5,"") | E20: =IF(AND(ISNUMBER(พอร์ตหุ้นรายตัว!J5),พอร์ตหุ้นรายตัว!J5>0),(พอร์ตหุ้นรายตัว!J5-พอร์ตหุ้นรายตัว!C5)*$E$2,"")
A21: =IF(AND(ISNUMBER(พอร์ตหุ้นรายตัว!J6),พอร์ตหุ้นรายตัว!J6>0),พอร์ตหุ้นรายตัว!B6,"") | B21: =IF(AND(ISNUMBER(พอร์ตหุ้นรายตัว!J6),พอร์ตหุ้นรายตัว!J6>0),พอร์ตหุ้นรายตัว!C6,"") | C21: =IF(AND(ISNUMBER(พอร์ตหุ้นรายตัว!J6),พอร์ตหุ้นรายตัว!J6>0),พอร์ตหุ้นรายตัว!J6,"") | D21: =IF(AND(ISNUMBER(พอร์ตหุ้นรายตัว!J6),พอร์ตหุ้นรายตัว!J6>0),พอร์ตหุ้นรายตัว!J6-พอร์ตหุ้นรายตัว!C6,"") | E21: =IF(AND(ISNUMBER(พอร์ตหุ้นรายตัว!J6),พอร์ตหุ้นรายตัว!J6>0),(พอร์ตหุ้นรายตัว!J6-พอร์ตหุ้นรายตัว!C6)*$E$2,"")
A22: RXRX (100 หุ้น) | B22: 418.75 | C22: 323.41 | D22: =C22-B22 | E22: =D22*$E$2
A23: RXRX (50 หุ้น) | B23: 209.375 | C23: 168.45 | D23: =C23-B23 | E23: =D23*$E$2
A24: =IF(AND(ISNUMBER(พอร์ตหุ้นรายตัว!J8),พอร์ตหุ้นรายตัว!J8>0),พอร์ตหุ้นรายตัว!B8,"") | B24: =IF(AND(ISNUMBER(พอร์ตหุ้นรายตัว!J8),พอร์ตหุ้นรายตัว!J8>0),พอร์ตหุ้นรายตัว!C8,"") | C24: =IF(AND(ISNUMBER(พอร์ตหุ้นรายตัว!J8),พอร์ตหุ้นรายตัว!J8>0),พอร์ตหุ้นรายตัว!J8,"") | D24: =IF(AND(ISNUMBER(พอร์ตหุ้นรายตัว!J8),พอร์ตหุ้นรายตัว!J8>0),พอร์ตหุ้นรายตัว!J8-พอร์ตหุ้นรายตัว!C8,"") | E24: =IF(AND(ISNUMBER(พอร์ตหุ้นรายตัว!J8),พอร์ตหุ้นรายตัว!J8>0),(พอร์ตหุ้นรายตัว!J8-พอร์ตหุ้นรายตัว!C8)*$E$2,"")
A25: =IF(AND(ISNUMBER(พอร์ตหุ้นรายตัว!J9),พอร์ตหุ้นรายตัว!J9>0),พอร์ตหุ้นรายตัว!B9,"") | B25: =IF(AND(ISNUMBER(พอร์ตหุ้นรายตัว!J9),พอร์ตหุ้นรายตัว!J9>0),พอร์ตหุ้นรายตัว!C9,"") | C25: =IF(AND(ISNUMBER(พอร์ตหุ้นรายตัว!J9),พอร์ตหุ้นรายตัว!J9>0),พอร์ตหุ้นรายตัว!J9,"") | D25: =IF(AND(ISNUMBER(พอร์ตหุ้นรายตัว!J9),พอร์ตหุ้นรายตัว!J9>0),พอร์ตหุ้นรายตัว!J9-พอร์ตหุ้นรายตัว!C9,"") | E25: =IF(AND(ISNUMBER(พอร์ตหุ้นรายตัว!J9),พอร์ตหุ้นรายตัว!J9>0),(พอร์ตหุ้นรายตัว!J9-พอร์ตหุ้นรายตัว!C9)*$E$2,"")
A26: =IF(AND(ISNUMBER(พอร์ตหุ้นรายตัว!J10),พอร์ตหุ้นรายตัว!J10>0),พอร์ตหุ้นรายตัว!B10,"") | B26: =IF(AND(ISNUMBER(พอร์ตหุ้นรายตัว!J10),พอร์ตหุ้นรายตัว!J10>0),พอร์ตหุ้นรายตัว!C10,"") | C26: =IF(AND(ISNUMBER(พอร์ตหุ้นรายตัว!J10),พอร์ตหุ้นรายตัว!J10>0),พอร์ตหุ้นรายตัว!J10,"") | D26: =IF(AND(ISNUMBER(พอร์ตหุ้นรายตัว!J10),พอร์ตหุ้นรายตัว!J10>0),พอร์ตหุ้นรายตัว!J10-พอร์ตหุ้นรายตัว!C10,"") | E26: =IF(AND(ISNUMBER(พอร์ตหุ้นรายตัว!J10),พอร์ตหุ้นรายตัว!J10>0),(พอร์ตหุ้นรายตัว!J10-พอร์ตหุ้นรายตัว!C10)*$E$2,"")
A27: =IF(AND(ISNUMBER(พอร์ตหุ้นรายตัว!J11),พอร์ตหุ้นรายตัว!J11>0),พอร์ตหุ้นรายตัว!B11,"") | B27: =IF(AND(ISNUMBER(พอร์ตหุ้นรายตัว!J11),พอร์ตหุ้นรายตัว!J11>0),พอร์ตหุ้นรายตัว!C11,"") | C27: =IF(AND(ISNUMBER(พอร์ตหุ้นรายตัว!J11),พอร์ตหุ้นรายตัว!J11>0),พอร์ตหุ้นรายตัว!J11,"") | D27: =IF(AND(ISNUMBER(พอร์ตหุ้นรายตัว!J11),พอร์ตหุ้นรายตัว!J11>0),พอร์ตหุ้นรายตัว!J11-พอร์ตหุ้นรายตัว!C11,"") | E27: =IF(AND(ISNUMBER(พอร์ตหุ้นรายตัว!J11),พอร์ตหุ้นรายตัว!J11>0),(พอร์ตหุ้นรายตัว!J11-พอร์ตหุ้นรายตัว!C11)*$E$2,"")
A28: =IF(AND(ISNUMBER(พอร์ตหุ้นรายตัว!J12),พอร์ตหุ้นรายตัว!J12>0),พอร์ตหุ้นรายตัว!B12,"") | B28: =IF(AND(ISNUMBER(พอร์ตหุ้นรายตัว!J12),พอร์ตหุ้นรายตัว!J12>0),พอร์ตหุ้นรายตัว!C12,"") | C28: =IF(AND(ISNUMBER(พอร์ตหุ้นรายตัว!J12),พอร์ตหุ้นรายตัว!J12>0),พอร์ตหุ้นรายตัว!J12,"") | D28: =IF(AND(ISNUMBER(พอร์ตหุ้นรายตัว!J12),พอร์ตหุ้นรายตัว!J12>0),พอร์ตหุ้นรายตัว!J12-พอร์ตหุ้นรายตัว!C12,"") | E28: =IF(AND(ISNUMBER(พอร์ตหุ้นรายตัว!J12),พอร์ตหุ้นรายตัว!J12>0),(พอร์ตหุ้นรายตัว!J12-พอร์ตหุ้นรายตัว!C12)*$E$2,"")
A29: =IF(AND(ISNUMBER(พอร์ตหุ้นรายตัว!J13),พอร์ตหุ้นรายตัว!J13>0),พอร์ตหุ้นรายตัว!B13,"") | B29: =IF(AND(ISNUMBER(พอร์ตหุ้นรายตัว!J13),พอร์ตหุ้นรายตัว!J13>0),พอร์ตหุ้นรายตัว!C13,"") | C29: =IF(AND(ISNUMBER(พอร์ตหุ้นรายตัว!J13),พอร์ตหุ้นรายตัว!J13>0),พอร์ตหุ้นรายตัว!J13,"") | D29: =IF(AND(ISNUMBER(พอร์ตหุ้นรายตัว!J13),พอร์ตหุ้นรายตัว!J13>0),พอร์ตหุ้นรายตัว!J13-พอร์ตหุ้นรายตัว!C13,"") | E29: =IF(AND(ISNUMBER(พอร์ตหุ้นรายตัว!J13),พอร์ตหุ้นรายตัว!J13>0),(พอร์ตหุ้นรายตัว!J13-พอร์ตหุ้นรายตัว!C13)*$E$2,"")
A30: =IF(AND(ISNUMBER(พอร์ตหุ้นรายตัว!J14),พอร์ตหุ้นรายตัว!J14>0),พอร์ตหุ้นรายตัว!B14,"") | B30: =IF(AND(ISNUMBER(พอร์ตหุ้นรายตัว!J14),พอร์ตหุ้นรายตัว!J14>0),พอร์ตหุ้นรายตัว!C14,"") | C30: =IF(AND(ISNUMBER(พอร์ตหุ้นรายตัว!J14),พอร์ตหุ้นรายตัว!J14>0),พอร์ตหุ้นรายตัว!J14,"") | D30: =IF(AND(ISNUMBER(พอร์ตหุ้นรายตัว!J14),พอร์ตหุ้นรายตัว!J14>0),พอร์ตหุ้นรายตัว!J14-พอร์ตหุ้นรายตัว!C14,"") | E30: =IF(AND(ISNUMBER(พอร์ตหุ้นรายตัว!J14),พอร์ตหุ้นรายตัว!J14>0),(พอร์ตหุ้นรายตัว!J14-พอร์ตหุ้นรายตัว!C14)*$E$2,"")
A31: =IF(AND(ISNUMBER(พอร์ตหุ้นรายตัว!J15),พอร์ตหุ้นรายตัว!J15>0),พอร์ตหุ้นรายตัว!B15,"") | B31: =IF(AND(ISNUMBER(พอร์ตหุ้นรายตัว!J15),พอร์ตหุ้นรายตัว!J15>0),พอร์ตหุ้นรายตัว!C15,"") | C31: =IF(AND(ISNUMBER(พอร์ตหุ้นรายตัว!J15),พอร์ตหุ้นรายตัว!J15>0),พอร์ตหุ้นรายตัว!J15,"") | D31: =IF(AND(ISNUMBER(พอร์ตหุ้นรายตัว!J15),พอร์ตหุ้นรายตัว!J15>0),พอร์ตหุ้นรายตัว!J15-พอร์ตหุ้นรายตัว!C15,"") | E31: =IF(AND(ISNUMBER(พอร์ตหุ้นรายตัว!J15),พอร์ตหุ้นรายตัว!J15>0),(พอร์ตหุ้นรายตัว!J15-พอร์ตหุ้นรายตัว!C15)*$E$2,"")
A32: =IF(AND(ISNUMBER(พอร์ตหุ้นรายตัว!J16),พอร์ตหุ้นรายตัว!J16>0),พอร์ตหุ้นรายตัว!B16,"") | B32: =IF(AND(ISNUMBER(พอร์ตหุ้นรายตัว!J16),พอร์ตหุ้นรายตัว!J16>0),พอร์ตหุ้นรายตัว!C16,"") | C32: =IF(AND(ISNUMBER(พอร์ตหุ้นรายตัว!J16),พอร์ตหุ้นรายตัว!J16>0),พอร์ตหุ้นรายตัว!J16,"") | D32: =IF(AND(ISNUMBER(พอร์ตหุ้นรายตัว!J16),พอร์ตหุ้นรายตัว!J16>0),พอร์ตหุ้นรายตัว!J16-พอร์ตหุ้นรายตัว!C16,"") | E32: =IF(AND(ISNUMBER(พอร์ตหุ้นรายตัว!J16),พอร์ตหุ้นรายตัว!J16>0),(พอร์ตหุ้นรายตัว!J16-พอร์ตหุ้นรายตัว!C16)*$E$2,"")
A33: =IF(AND(ISNUMBER(พอร์ตหุ้นรายตัว!J17),พอร์ตหุ้นรายตัว!J17>0),พอร์ตหุ้นรายตัว!B17,"") | B33: =IF(AND(ISNUMBER(พอร์ตหุ้นรายตัว!J17),พอร์ตหุ้นรายตัว!J17>0),พอร์ตหุ้นรายตัว!C17,"") | C33: =IF(AND(ISNUMBER(พอร์ตหุ้นรายตัว!J17),พอร์ตหุ้นรายตัว!J17>0),พอร์ตหุ้นรายตัว!J17,"") | D33: =IF(AND(ISNUMBER(พอร์ตหุ้นรายตัว!J17),พอร์ตหุ้นรายตัว!J17>0),พอร์ตหุ้นรายตัว!J17-พอร์ตหุ้นรายตัว!C17,"") | E33: =IF(AND(ISNUMBER(พอร์ตหุ้นรายตัว!J17),พอร์ตหุ้นรายตัว!J17>0),(พอร์ตหุ้นรายตัว!J17-พอร์ตหุ้นรายตัว!C17)*$E$2,"")
A34: =IF(AND(ISNUMBER(พอร์ตหุ้นรายตัว!J18),พอร์ตหุ้นรายตัว!J18>0),พอร์ตหุ้นรายตัว!B18,"") | B34: =IF(AND(ISNUMBER(พอร์ตหุ้นรายตัว!J18),พอร์ตหุ้นรายตัว!J18>0),พอร์ตหุ้นรายตัว!C18,"") | C34: =IF(AND(ISNUMBER(พอร์ตหุ้นรายตัว!J18),พอร์ตหุ้นรายตัว!J18>0),พอร์ตหุ้นรายตัว!J18,"") | D34: =IF(AND(ISNUMBER(พอร์ตหุ้นรายตัว!J18),พอร์ตหุ้นรายตัว!J18>0),พอร์ตหุ้นรายตัว!J18-พอร์ตหุ้นรายตัว!C18,"") | E34: =IF(AND(ISNUMBER(พอร์ตหุ้นรายตัว!J18),พอร์ตหุ้นรายตัว!J18>0),(พอร์ตหุ้นรายตัว!J18-พอร์ตหุ้นรายตัว!C18)*$E$2,"")
A35: =IF(AND(ISNUMBER(พอร์ตหุ้นรายตัว!J19),พอร์ตหุ้นรายตัว!J19>0),พอร์ตหุ้นรายตัว!B19,"") | B35: =IF(AND(ISNUMBER(พอร์ตหุ้นรายตัว!J19),พอร์ตหุ้นรายตัว!J19>0),พอร์ตหุ้นรายตัว!C19,"") | C35: =IF(AND(ISNUMBER(พอร์ตหุ้นรายตัว!J19),พอร์ตหุ้นรายตัว!J19>0),พอร์ตหุ้นรายตัว!J19,"") | D35: =IF(AND(ISNUMBER(พอร์ตหุ้นรายตัว!J19),พอร์ตหุ้นรายตัว!J19>0),พอร์ตหุ้นรายตัว!J19-พอร์ตหุ้นรายตัว!C19,"") | E35: =IF(AND(ISNUMBER(พอร์ตหุ้นรายตัว!J19),พอร์ตหุ้นรายตัว!J19>0),(พอร์ตหุ้นรายตัว!J19-พอร์ตหุ้นรายตัว!C19)*$E$2,"")
A36: =IF(AND(ISNUMBER(พอร์ตหุ้นรายตัว!J20),พอร์ตหุ้นรายตัว!J20>0),พอร์ตหุ้นรายตัว!B20,"") | B36: =IF(AND(ISNUMBER(พอร์ตหุ้นรายตัว!J20),พอร์ตหุ้นรายตัว!J20>0),พอร์ตหุ้นรายตัว!C20,"") | C36: =IF(AND(ISNUMBER(พอร์ตหุ้นรายตัว!J20),พอร์ตหุ้นรายตัว!J20>0),พอร์ตหุ้นรายตัว!J20,"") | D36: =IF(AND(ISNUMBER(พอร์ตหุ้นรายตัว!J20),พอร์ตหุ้นรายตัว!J20>0),พอร์ตหุ้นรายตัว!J20-พอร์ตหุ้นรายตัว!C20,"") | E36: =IF(AND(ISNUMBER(พอร์ตหุ้นรายตัว!J20),พอร์ตหุ้นรายตัว!J20>0),(พอร์ตหุ้นรายตัว!J20-พอร์ตหุ้นรายตัว!C20)*$E$2,"")
A38: =IF(AND(ISNUMBER(พอร์ตหุ้นรายตัว!J21),พอร์ตหุ้นรายตัว!J21>0),พอร์ตหุ้นรายตัว!B21,"") | B38: =IF(AND(ISNUMBER(พอร์ตหุ้นรายตัว!J21),พอร์ตหุ้นรายตัว!J21>0),พอร์ตหุ้นรายตัว!C21,"") | C38: =IF(AND(ISNUMBER(พอร์ตหุ้นรายตัว!J21),พอร์ตหุ้นรายตัว!J21>0),พอร์ตหุ้นรายตัว!J21,"") | D38: =IF(AND(ISNUMBER(พอร์ตหุ้นรายตัว!J21),พอร์ตหุ้นรายตัว!J21>0),พอร์ตหุ้นรายตัว!J21-พอร์ตหุ้นรายตัว!C21,"") | E38: =IF(AND(ISNUMBER(พอร์ตหุ้นรายตัว!J21),พอร์ตหุ้นรายตัว!J21>0),(พอร์ตหุ้นรายตัว!J21-พอร์ตหุ้นรายตัว!C21)*$E$2,"")
A39: =IF(AND(ISNUMBER(พอร์ตหุ้นรายตัว!J22),พอร์ตหุ้นรายตัว!J22>0),พอร์ตหุ้นรายตัว!B22,"") | B39: =IF(AND(ISNUMBER(พอร์ตหุ้นรายตัว!J22),พอร์ตหุ้นรายตัว!J22>0),พอร์ตหุ้นรายตัว!C22,"") | C39: =IF(AND(ISNUMBER(พอร์ตหุ้นรายตัว!J22),พอร์ตหุ้นรายตัว!J22>0),พอร์ตหุ้นรายตัว!J22,"") | D39: =IF(AND(ISNUMBER(พอร์ตหุ้นรายตัว!J22),พอร์ตหุ้นรายตัว!J22>0),พอร์ตหุ้นรายตัว!J22-พอร์ตหุ้นรายตัว!C22,"") | E39: =IF(AND(ISNUMBER(พอร์ตหุ้นรายตัว!J22),พอร์ตหุ้นรายตัว!J22>0),(พอร์ตหุ้นรายตัว!J22-พอร์ตหุ้นรายตัว!C22)*$E$2,"")
A40: =IF(AND(ISNUMBER(พอร์ตหุ้นรายตัว!J23),พอร์ตหุ้นรายตัว!J23>0),พอร์ตหุ้นรายตัว!B23,"") | B40: =IF(AND(ISNUMBER(พอร์ตหุ้นรายตัว!J23),พอร์ตหุ้นรายตัว!J23>0),พอร์ตหุ้นรายตัว!C23,"") | C40: =IF(AND(ISNUMBER(พอร์ตหุ้นรายตัว!J23),พอร์ตหุ้นรายตัว!J23>0),พอร์ตหุ้นรายตัว!J23,"") | D40: =IF(AND(ISNUMBER(พอร์ตหุ้นรายตัว!J23),พอร์ตหุ้นรายตัว!J23>0),พอร์ตหุ้นรายตัว!J23-พอร์ตหุ้นรายตัว!C23,"") | E40: =IF(AND(ISNUMBER(พอร์ตหุ้นรายตัว!J23),พอร์ตหุ้นรายตัว!J23>0),(พอร์ตหุ้นรายตัว!J23-พอร์ตหุ้นรายตัว!C23)*$E$2,"")
A41: =IF(AND(ISNUMBER(พอร์ตหุ้นรายตัว!J24),พอร์ตหุ้นรายตัว!J24>0),พอร์ตหุ้นรายตัว!B24,"") | B41: =IF(AND(ISNUMBER(พอร์ตหุ้นรายตัว!J24),พอร์ตหุ้นรายตัว!J24>0),พอร์ตหุ้นรายตัว!C24,"") | C41: =IF(AND(ISNUMBER(พอร์ตหุ้นรายตัว!J24),พอร์ตหุ้นรายตัว!J24>0),พอร์ตหุ้นรายตัว!J24,"") | D41: =IF(AND(ISNUMBER(พอร์ตหุ้นรายตัว!J24),พอร์ตหุ้นรายตัว!J24>0),พอร์ตหุ้นรายตัว!J24-พอร์ตหุ้นรายตัว!C24,"") | E41: =IF(AND(ISNUMBER(พอร์ตหุ้นรายตัว!J24),พอร์ตหุ้นรายตัว!J24>0),(พอร์ตหุ้นรายตัว!J24-พอร์ตหุ้นรายตัว!C24)*$E$2,"")
A43: 📊 รวมกำไร/ขาดทุน (หุ้นทั่วไป) | D43: =SUM(D5:D41) | E43: =SUM(E5:E41)
...

Sheet รายรับ-รายจ่าย
A1: สรุปรายรับ - รายจ่าย ประจำปี | F1: 💳 รายจ่ายรายปีที่ต้องจ่าย
A2: รายการ | B2: ต่อเดือน (บาท) | C2: ต่อปี (บาท) | F2: รายการ | G2: เดือน | H2: จำนวน (บาท) | I2: ✓ จ่ายแล้ว
A3: 💰 รายรับ | F3: ส่วนกลางคอนโด | G3: เดือน 2 | H3: 21000 | I3: ☑
A4: ยอดเงินเดือนต่อครั้ง (แบ่งจ่าย 2 ครั้ง/เดือน) | B4: 44230 | F4: ประกันรถ | G4: เดือน 3 | H4: 15000 | I4: ☑
A5: เงินเดือนรวม (×2) | B5: =B4*2 | C5: =B4*24 | F5: ประกันชีวิต | G5: เดือน 4 | H5: 22300 | I5: ☐
A6: หัก: กองทุนสำรองเลี้ยงชีพ (ต่อครั้ง) | B6: 2212 | F6: ประกันชีวิต | G6: เดือน 7 | H6: 53597 | I6: ☐
A7: หัก: ภาษี (ต่อครั้ง) | B7: 2590.4 | F7: ประกันชีวิต | G7: เดือน 8 | H7: 26426 | I7: ☐
A8: รวมถูกหัก (กองทุน + ภาษี) ×2 | B8: =(B6+B7)*2 | C8: =(B6+B7)*24 | F8: รวมทั้งหมด | H8: =SUM(H3:H7)
A9: ↳ กองทุนสำรองเลี้ยงชีพ ×2 (บันทึกเป็นเงินเก็บอัตโนมัติ) | B9: =B6*2 | C9: =B6*24
A10: ✦ เงินเดือนสุทธิ (หลังหัก) | B10: =B5-B8 | C10: =C5-C8
A12: 📌 รายจ่าย
A13: ประกันรถ (ต่อปี) | B13: =C13/12 | C13: 15000
A14: ค่าส่วนกลางคอนโด (ต่อปี) | B14: =C14/12 | C14: 21000
A15: ค่าคอนโด | B15: 12300 | C15: =B15*12
A16: ค่าประกัน | B16: =C16/12 | C16: =H5+H6+H7
A17: ค่าบัตรเครดิต | B17: 6000 | C17: =B17*12
A18: ค่าโทรศัพท์ | B18: 373 | C18: =B18*12
A19: ค่าเน็ตบ้าน | B19: 535 | C19: =B19*12
A20: ค่าไฟ (บ้าน + คอนโด) | B20: 1000 | C20: =B20*12
A21: โป๊ะคอนโด | B21: 7000 | C21: =B21*12
A22: ค่ากินอยู่ | B22: 12000 | C22: =B22*12
A23: Claude Pro (AI Subscription) $17/mo (รายปี) | B23: 556.92 | C23: =B23*12
A24: รวมรายจ่าย | B24: =B13+B14+B15+B16+B17+B18+B19+B20+B21+B22+B23 | C24: =C13+C14+C15+C16+C17+C18+C19+C20+C21+C22+C23
A26: 💎 เงินเก็บ
A27: กองทุนสำรองเลี้ยงชีพ (หักแล้ว ✓) | B27: =B6*2 | C27: =B6*24
A28: ลงทุนหุ้น | B28: 20000 | C28: =B28*12
A29: เก็บกับต่อมา | B29: 5000 | C29: =B29*12
A30: รวมเงินเก็บ (ไม่รวมกองทุน) | B30: =B28+B29 | C30: =C28+C29
A32: 📊 รวมรายจ่าย + เงินเก็บทั้งหมด | B32: =B24+B30 | C32: =C24+C30
A33: ✅ คงเหลือสุทธิ (หลังหักทั้งหมด) | B33: =B10-B32 | C33: =C10-C32

Sheet แผนจ่ายต่อรอบ
A1: แผนการจ่ายเงินต่อรอบ
A2: 💡 รายรับ = ยอดหลังหักกองทุนสำรองเลี้ยงชีพ + ภาษีแล้ว
A4: 🗓️ รอบที่ 1 — วันที่ 20
A5: รายการ | B5: จำนวน (บาท) | C5: หมายเหตุ
A6: 💰 รายรับ (หลังหักกองทุน + ภาษี) | B6: ='รายรับ-รายจ่าย'!B10/2 | C6: เงินเดือนสุทธิ ÷ 2
A7: ประกันรถ | B7: ='รายรับ-รายจ่าย'!B13 | C7: ตั้งสำรอง 1/12 ต่อปี
A8: ค่าส่วนกลางคอนโด | B8: ='รายรับ-รายจ่าย'!B14 | C8: ตั้งสำรอง 1/12 ต่อปี
A9: ค่าคอนโด | B9: ='รายรับ-รายจ่าย'!B15
A10: โป๊ะคอนโด | B10: ='รายรับ-รายจ่าย'!B21
A11: ค่าโทรศัพท์ | B11: ='รายรับ-รายจ่าย'!B18
A12: ค่าไฟ | B12: ='รายรับ-รายจ่าย'!B20
A13: ค่าบัตรเครดิต | B13: ='รายรับ-รายจ่าย'!B17
A14: ค่าเน็ตบ้าน | B14: ='รายรับ-รายจ่าย'!B19
A15: เก็บกับต่อมา | B15: ='รายรับ-รายจ่าย'!B29/2 | C15: 5,000 ÷ 2
A16: ค่ากินอยู่ | B16: ='รายรับ-รายจ่าย'!B22/2 | C16: 12,000 ÷ 2
A17: รวมรายจ่ายรอบที่ 1 | B17: =B7+B8+B9+B10+B11+B12+B13+B14+B15+B16
A18: ✅ คงเหลือหลังรอบที่ 1 | B18: =B6-B17
A20: 🗓️ รอบที่ 2 — วันที่ 5
A21: รายการ | B21: จำนวน (บาท) | C21: หมายเหตุ
A22: 💰 รายรับ (หลังหักกองทุน + ภาษี) | B22: ='รายรับ-รายจ่าย'!B10/2 | C22: เงินเดือนสุทธิ ÷ 2
A23: ค่ากินอยู่ | B23: ='รายรับ-รายจ่าย'!B22/2 | C23: 12,000 ÷ 2
A24: ค่าประกัน | B24: ='รายรับ-รายจ่าย'!B16
A25: ลงทุนหุ้น | B25: ='รายรับ-รายจ่าย'!B28
A26: เก็บกับต่อมา | B26: ='รายรับ-รายจ่าย'!B29/2 | C26: 5,000 ÷ 2
A27: Claude Pro | B27: ='รายรับ-รายจ่าย'!B23 | C27: $17/mo (รายปี)
A28: รวมรายจ่ายรอบที่ 2 | B28: =B23+B24+B25+B26+B27
A29: ✅ คงเหลือหลังรอบที่ 2 | B29: =B22-B28
